Workbook

Sheet README
A1: EV vs CNG vs Diesel vs Ethanol-Petrol — India Vehicle Cost Model (July 2026)
A3: HOW TO USE
A4: 1. Assumptions tab: pick your city (yellow cell) and edit blue inputs/yellow levers (E20 drop, usage km, charging mix). The whole model reprices.
A5: 2. Cities tab: petrol/diesel/CNG/electricity and state VAT for 6 metros, plus cost per km by city.
A6: 3. CostPerKm: running cost per km by vehicle & powertrain for the selected city (petrol includes the E20 penalty).
A7: 4. EthanolImpact: what ethanol blending costs a petrol owner.
A8: 5. TCO_Scenarios: fuel + maintenance + premium and payback across Low/Average/High usage.
A9: 6. TaxStructure: why petrol/diesel are taxed by BOTH centre and state, while ethanol carries only 5% GST (federal).
A10: 7. Checks: 13 automated consistency checks (should all read PASS).
A12: COLOUR LEGEND
A13: Blue = editable input. Yellow = key lever. Green = pulled from another sheet. Black = calculated.
A15: KEY FINDINGS
... A24: Representative estimates for comparison, not quotes. VAT rates are indicative; states add cesses. Verify local prices before purchase.

Sheet Assumptions
A1: ASSUMPTIONS & INPUT LEVERS
A2: Blue = editable input. Yellow = key lever. Green = pulled from another sheet. Pick a city and the whole model reprices.
A4: 1. Location — pick your city
A5: Item | B5: Value | C5: Unit | D5: Source / Note
A6: Selected city | B6: Delhi | C6: name | D6: LEVER: type a city listed on the Cities tab
A7: Petrol price (E20 pump) | B7: =INDEX(Cities!$B$4:$B$9,MATCH(Assumptions!$B$6,Cities!$A$4:$A$9,0)) -> 102.12 | C7: Rs/litre | D7: Auto from Cities tab (PPAC July 2026)
A8: Diesel price | B8: =INDEX(Cities!$C$4:$C$9,MATCH(Assumptions!$B$6,Cities!$A$4:$A$9,0)) -> 95.2 | C8: Rs/litre | D8: Auto from Cities tab
A9: CNG price | B9: =INDEX(Cities!$D$4:$D$9,MATCH(Assumptions!$B$6,Cities!$A$4:$A$9,0)) -> 83.09 | C9: Rs/kg | D9: Auto from Cities tab
A10: Electricity - home | B10: =INDEX(Cities!$E$4:$E$9,MATCH(Assumptions!$B$6,Cities!$A$4:$A$9,0)) -> 8 | C10: Rs/kWh | D10: Auto from Cities tab (indicative domestic slab)
A11: 2. EV charging & ethanol
A12: Item | B12: Value | C12: Unit | D12: Source / Note
A13: Electricity - public DC fast | B13: 21 | C13: Rs/kWh | D13: Midpoint of Rs 18-24 (2026)
A14: Share of home charging | B14: 0.8 | C14: % kWh | D14: Typical private EV owner
A15: Blended EV electricity price | B15: =Assumptions!$B$10*Assumptions!$B$14+Assumptions!$B$13*(1-Assumptions!$B$14) -> 10.6 | C15: Rs/kWh | D15: Weighted home + public
A16: E10 mileage drop | B16: 0.02 | C16: % loss | D16: ~2% baseline (ARAI/SIAM)
A17: E20 mileage drop (SELECTED) | B17: 0.04 | C17: % loss | D17: LEVER: SIAM 2-4%, ARAI 2-6%; older cars up to ~12%
A18: 3. Baseline real-world mileage (per energy unit)
A19: Item | B19: Value | C19: Unit | D19: Source / Note
A20: Vehicle type | B20: Petrol km/L (E0) | C20: Diesel km/L | D20: CNG km/kg | E20: EV km/kWh
A21: Two-wheeler | B21: 55 | C21: n/a | D21: 102 | E21: 30 | F21: Petrol commuter; CNG=Bajaj Freedom 125
A22: Hatchback | B22: 16 | C22: n/a | D22: 28 | E22: 7.5 | F22: Swift/WagonR class
A23: Sedan | B23: 15 | C23: 22 | D23: 26 | E23: 7 | F23: Dzire/Verna class
A24: Compact SUV | B24: 13 | C24: 19 | D24: 22 | E24: 6.5 | F24: Nexon/Brezza class
A26: 4. Vehicle prices & powertrain premium (on-road, Rs)
A27: Item | B27: Value | C27: Unit | D27: Source / Note
A28: Vehicle type | B28: Petrol base | C28: Diesel premium | D28: CNG premium | E28: EV premium
A29: Two-wheeler | B29: 90000 | C29: n/a | D29: 15000 | E29: 45000
A30: Hatchback | B30: 700000 | C30: n/a | D30: 90000 | E30: 450000
A31: Sedan | B31: 900000 | C31: 120000 | D31: 95000 | E31: 500000
A32: Compact SUV | B32: 1150000 | C32: 150000 | D32: 110000 | E32: 400000
A34: 5. Annual maintenance (Rs/year)
A35: Item | B35: Value | C35: Unit | D35: Source / Note
A36: Two-wheeler - petrol | B36: 2000 | C36: Rs/yr | D36: Indicative
A37: Two-wheeler - CNG | B37: 2600 | C37: Rs/yr | D37: CNG system upkeep
A38: Two-wheeler - EV | B38: 1000 | C38: Rs/yr | D38: Fewer parts
A39: Car - petrol | B39: 6000 | C39: Rs/yr | D39: Indicative
A40: Car - diesel | B40: 9000 | C40: Rs/yr | D40: Higher service cost
A41: Car - CNG | B41: 8500 | C41: Rs/yr | D41: Filters, cylinder test
A42: Car - EV | B42: 3500 | C42: Rs/yr | D42: Lower service needs
A43: 6. Usage scenarios & horizon
...

Sheet Cities
A1: CITY FUEL PRICES (PPAC basis, July 2026) & COST PER KM
A2: Blue = editable price/tax input. Green = cost per km computed from Assumptions mileages. Petrol/km reflects the selected E20 drop.
A3: City | B3: Petrol Rs/L | C3: Diesel Rs/L | D3: CNG Rs/kg | E3: Elec home Rs/kWh | F3: Petrol VAT % | G3: Diesel VAT % | H3: Petrol/km (hatch) | I3: Diesel/km (SUV) | J3: CNG/km (hatch) | K3: EV/km (hatch)
A4: Delhi | B4: 102.12 | C4: 95.2 | D4: 83.09 | E4: 8 | F4: 0.194 | G4: 0.1675 | H4: =B4/(Assumptions!$B$22*(1-Assumptions!$B$17)) -> 6.6484375 | I4: =C4/Assumptions!$C$24 -> 5.0105263 | J4: =D4/Assumptions!$D$22 -> 2.9675 | K4: =(E4*Assumptions!$B$14+Assumptions!$B$13*(1-Assumptions!$B$14))/Assumptions!$E$22 -> 1.4133333
A5: Mumbai | B5: 111.21 | C5: 97.83 | D5: 86 | E5: 11 | F5: 0.25 | G5: 0.21 | H5: =B5/(Assumptions!$B$22*(1-Assumptions!$B$17)) -> 7.2402344 | I5: =C5/Assumptions!$C$24 -> 5.1489474 | J5: =D5/Assumptions!$D$22 -> 3.0714286 | K5: =(E5*Assumptions!$B$14+Assumptions!$B$13*(1-Assumptions!$B$14))/Assumptions!$E$22 -> 1.7333333
A6: Kolkata | B6: 113.51 | C6: 99.82 | D6: 93.5 | E6: 9 | F6: 0.25 | G6: 0.175 | H6: =B6/(Assumptions!$B$22*(1-Assumptions!$B$17)) -> 7.389974 | I6: =C6/Assumptions!$C$24 -> 5.2536842 | J6: =D6/Assumptions!$D$22 -> 3.3392857 | K6: =(E6*Assumptions!$B$14+Assumptions!$B$13*(1-Assumptions!$B$14))/Assumptions!$E$22 -> 1.52
A7: Chennai | B7: 107.76 | C7: 99.55 | D7: 97 | E7: 8 | F7: 0.18 | G7: 0.14 | H7: =B7/(Assumptions!$B$22*(1-Assumptions!$B$17)) -> 7.015625 | I7: =C7/Assumptions!$C$24 -> 5.2394737 | J7: =D7/Assumptions!$D$22 -> 3.4642857 | K7: =(E7*Assumptions!$B$14+Assumptions!$B$13*(1-Assumptions!$B$14))/Assumptions!$E$22 -> 1.4133333
A8: Bengaluru | B8: 111.68 | C8: 99.56 | D8: 97 | E8: 9 | F8: 0.2984 | G8: 0.1844 | H8: =B8/(Assumptions!$B$22*(1-Assumptions!$B$17)) -> 7.2708333 | I8: =C8/Assumptions!$C$24 -> 5.24 | J8: =D8/Assumptions!$D$22 -> 3.4642857 | K8: =(E8*Assumptions!$B$14+Assumptions!$B$13*(1-Assumptions!$B$14))/Assumptions!$E$22 -> 1.52
A9: Hyderabad | B9: 115.69 | C9: 103.82 | D9: 97 | E9: 9.5 | F9: 0.352 | G9: 0.27 | H9: =B9/(Assumptions!$B$22*(1-Assumptions!$B$17)) -> 7.531901 | I9: =C9/Assumptions!$C$24 -> 5.4642105 | J9: =D9/Assumptions!$D$22 -> 3.4642857 | K9: =(E9*Assumptions!$B$14+Assumptions!$B$13*(1-Assumptions!$B$14))/Assumptions!$E$22 -> 1.5733333
A11: VAT rates are indicative effective rates; several states add fixed per-litre cesses, so exact retail may differ slightly. Central excise (federal) is uniform: Rs 13/L petrol, Rs 10/L diesel.

Sheet CostPerKm
A1: RUNNING COST PER KILOMETRE (selected city)
A2: Petrol reflects the selected E20 mileage drop. Green = pulled from Assumptions.
A4: Vehicle type | B4: Powertrain | C4: Baseline mileage | D4: Effective mileage | E4: Unit | F4: Fuel/energy price | G4: Cost per km (Rs)
A5: Two-wheeler | B5: Petrol | C5: =Assumptions!$B$21 -> 55 | D5: =Assumptions!$B$21*(1-Assumptions!$B$17) -> 52.8 | E5: km/L | F5: =Assumptions!$B$7 -> 102.12 | G5: =F5/D5 -> 1.9340909
A6: Two-wheeler | B6: CNG | C6: =Assumptions!$D$21 -> 102 | D6: =Assumptions!$D$21 -> 102 | E6: km/kg | F6: =Assumptions!$B$9 -> 83.09 | G6: =F6/D6 -> 0.81460784
A7: Two-wheeler | B7: EV | C7: =Assumptions!$E$21 -> 30 | D7: =Assumptions!$E$21 -> 30 | E7: km/kWh | F7: =Assumptions!$B$15 -> 10.6 | G7: =F7/D7 -> 0.35333333
A8: Hatchback | B8: Petrol | C8: =Assumptions!$B$22 -> 16 | D8: =Assumptions!$B$22*(1-Assumptions!$B$17) -> 15.36 | E8: km/L | F8: =Assumptions!$B$7 -> 102.12 | G8: =F8/D8 -> 6.6484375
A9: Hatchback | B9: CNG | C9: =Assumptions!$D$22 -> 28 | D9: =Assumptions!$D$22 -> 28 | E9: km/kg | F9: =Assumptions!$B$9 -> 83.09 | G9: =F9/D9 -> 2.9675
A10: Hatchback | B10: EV | C10: =Assumptions!$E$22 -> 7.5 | D10: =Assumptions!$E$22 -> 7.5 | E10: km/kWh | F10: =Assumptions!$B$15 -> 10.6 | G10: =F10/D10 -> 1.4133333
A11: Sedan | B11: Petrol | C11: =Assumptions!$B$23 -> 15 | D11: =Assumptions!$B$23*(1-Assumptions!$B$17) -> 14.4 | E11: km/L | F11: =Assumptions!$B$7 -> 102.12 | G11: =F11/D11 -> 7.0916667
A12: Sedan | B12: Diesel | C12: =Assumptions!$C$23 -> 22 | D12: =Assumptions!$C$23 -> 22 | E12: km/L | F12: =Assumptions!$B$8 -> 95.2 | G12: =F12/D12 -> 4.3272727
A13: Sedan | B13: CNG | C13: =Assumptions!$D$23 -> 26 | D13: =Assumptions!$D$23 -> 26 | E13: km/kg | F13: =Assumptions!$B$9 -> 83.09 | G13: =F13/D13 -> 3.1957692
A14: Sedan | B14: EV | C14: =Assumptions!$E$23 -> 7 | D14: =Assumptions!$E$23 -> 7 | E14: km/kWh | F14: =Assumptions!$B$15 -> 10.6 | G14: =F14/D14 -> 1.5142857
A15: Compact SUV | B15: Petrol | C15: =Assumptions!$B$24 -> 13 | D15: =Assumptions!$B$24*(1-Assumptions!$B$17) -> 12.48 | E15: km/L | F15: =Assumptions!$B$7 -> 102.12 | G15: =F15/D15 -> 8.1826923
A16: Compact SUV | B16: Diesel | C16: =Assumptions!$C$24 -> 19 | D16: =Assumptions!$C$24 -> 19 | E16: km/L | F16: =Assumptions!$B$8 -> 95.2 | G16: =F16/D16 -> 5.0105263
A17: Compact SUV | B17: CNG | C17: =Assumptions!$D$24 -> 22 | D17: =Assumptions!$D$24 -> 22 | E17: km/kg | F17: =Assumptions!$B$9 -> 83.09 | G17: =F17/D17 -> 3.7768182
A18: Compact SUV | B18: EV | C18: =Assumptions!$E$24 -> 6.5 | D18: =Assumptions!$E$24 -> 6.5 | E18: km/kWh | F18: =Assumptions!$B$15 -> 10.6 | G18: =F18/D18 -> 1.6307692

Sheet EthanolImpact
A1: ETHANOL BLENDING: WHAT IT COSTS A PETROL OWNER
A2: E10/E20 vs pure petrol (E0). Rs/yr at Average usage, selected-city petrol price.
A4: Vehicle | B4: E0 km/L | C4: E10 km/L | D4: E20 km/L | E4: E0 cost/km | F4: E20 cost/km | G4: Extra Rs/km | H4: Extra Rs/yr (avg)
A5: Two-wheeler | B5: =Assumptions!$B$21 -> 55 | C5: =Assumptions!$B$21*(1-Assumptions!$B$16) -> 53.9 | D5: =Assumptions!$B$21*(1-Assumptions!$B$17) -> 52.8 | E5: =Assumptions!$B$7/Assumptions!$B$21 -> 1.8567273 | F5: =Assumptions!$B$7/D5 -> 1.9340909 | G5: =F5-E5 -> 0.077363636 | H5: =G5*Assumptions!$B$46 -> 1160.4545
A6: Hatchback | B6: =Assumptions!$B$22 -> 16 | C6: =Assumptions!$B$22*(1-Assumptions!$B$16) -> 15.68 | D6: =Assumptions!$B$22*(1-Assumptions!$B$17) -> 15.36 | E6: =Assumptions!$B$7/Assumptions!$B$22 -> 6.3825 | F6: =Assumptions!$B$7/D6 -> 6.6484375 | G6: =F6-E6 -> 0.2659375 | H6: =G6*Assumptions!$B$46 -> 3989.0625
A7: Sedan | B7: =Assumptions!$B$23 -> 15 | C7: =Assumptions!$B$23*(1-Assumptions!$B$16) -> 14.7 | D7: =Assumptions!$B$23*(1-Assumptions!$B$17) -> 14.4 | E7: =Assumptions!$B$7/Assumptions!$B$23 -> 6.808 | F7: =Assumptions!$B$7/D7 -> 7.0916667 | G7: =F7-E7 -> 0.28366667 | H7: =G7*Assumptions!$B$46 -> 4255
A8: Compact SUV | B8: =Assumptions!$B$24 -> 13 | C8: =Assumptions!$B$24*(1-Assumptions!$B$16) -> 12.74 | D8: =Assumptions!$B$24*(1-Assumptions!$B$17) -> 12.48 | E8: =Assumptions!$B$7/Assumptions!$B$24 -> 7.8553846 | F8: =Assumptions!$B$7/D8 -> 8.1826923 | G8: =F8-E8 -> 0.32730769 | H8: =G8*Assumptions!$B$46 -> 4909.6154

Sheet TCO_Scenarios
A1: TOTAL COST OF OWNERSHIP BY USAGE SCENARIO (selected city)
A2: Fuel + maintenance over the horizon, plus upfront premium vs petrol. Payback = years for savings to repay the premium.
A4: Scenario | B4: Vehicle | C4: Powertrain | D4: Annual km | E4: Cost/km | F4: Annual fuel | G4: Annual maint | H4: Annual total | I4: Premium vs petrol | J4: TCO horizon | K4: Saving/yr vs petrol | L4: Payback yrs
A5: Low | B5: Two-wheeler | C5: Petrol | D5: =Assumptions!$B$45 -> 8000 | E5: =CostPerKm!$G$5 -> 1.9340909 | F5: =D5*E5 -> 15472.727 | G5: =Assumptions!$B$36 -> 2000 | H5: =F5+G5 -> 17472.727 | I5: =0 -> 0 | J5: =I5+H5*Assumptions!$B$48 -> 87363.636 | K5: =($D5*CostPerKm!$G$5+Assumptions!$B$36)-H5 -> 0 | L5: =IF(K5<=0,"never",IF(I5=0,0,I5/K5)) -> never
A6: Low | B6: Two-wheeler | C6: CNG | D6: =Assumptions!$B$45 -> 8000 | E6: =CostPerKm!$G$6 -> 0.81460784 | F6: =D6*E6 -> 6516.8627 | G6: =Assumptions!$B$37 -> 2600 | H6: =F6+G6 -> 9116.8627 | I6: =Assumptions!$D$29 -> 15000 | J6: =I6+H6*Assumptions!$B$48 -> 60584.314 | K6: =($D6*CostPerKm!$G$5+Assumptions!$B$36)-H6 -> 8355.8645 | L6: =IF(K6<=0,"never",IF(I6=0,0,I6/K6)) -> 1.7951464
A7: Low | B7: Two-wheeler | C7: EV | D7: =Assumptions!$B$45 -> 8000 | E7: =CostPerKm!$G$7 -> 0.35333333 | F7: =D7*E7 -> 2826.6667 | G7: =Assumptions!$B$38 -> 1000 | H7: =F7+G7 -> 3826.6667 | I7: =Assumptions!$E$29 -> 45000 | J7: =I7+H7*Assumptions!$B$48 -> 64133.333 | K7: =($D7*CostPerKm!$G$5+Assumptions!$B$36)-H7 -> 13646.061 | L7: =IF(K7<=0,"never",IF(I7=0,0,I7/K7)) -> 3.297655
A8: Low | B8: Hatchback | C8: Petrol | D8: =Assumptions!$B$45 -> 8000 | E8: =CostPerKm!$G$8 -> 6.6484375 | F8: =D8*E8 -> 53187.5 | G8: =Assumptions!$B$39 -> 6000 | H8: =F8+G8 -> 59187.5 | I8: =0 -> 0 | J8: =I8+H8*Assumptions!$B$48 -> 295937.5 | K8: =($D8*CostPerKm!$G$8+Assumptions!$B$39)-H8 -> 0 | L8: =IF(K8<=0,"never",IF(I8=0,0,I8/K8)) -> never
A9: Low | B9: Hatchback | C9: CNG | D9: =Assumptions!$B$45 -> 8000 | E9: =CostPerKm!$G$9 -> 2.9675 | F9: =D9*E9 -> 23740 | G9: =Assumptions!$B$41 -> 8500 | H9: =F9+G9 -> 32240 | I9: =Assumptions!$D$30 -> 90000 | J9: =I9+H9*Assumptions!$B$48 -> 251200 | K9: =($D9*CostPerKm!$G$8+Assumptions!$B$39)-H9 -> 26947.5 | L9: =IF(K9<=0,"never",IF(I9=0,0,I9/K9)) -> 3.3398274
A10: Low | B10: Hatchback | C10: EV | D10: =Assumptions!$B$45 -> 8000 | E10: =CostPerKm!$G$10 -> 1.4133333 | F10: =D10*E10 -> 11306.667 | G10: =Assumptions!$B$42 -> 3500 | H10: =F10+G10 -> 14806.667 | I10: =Assumptions!$E$30 -> 450000 | J10: =I10+H10*Assumptions!$B$48 -> 524033.33 | K10: =($D10*CostPerKm!$G$8+Assumptions!$B$39)-H10 -> 44380.833 | L10: =IF(K10<=0,"never",IF(I10=0,0,I10/K10)) -> 10.139512
A11: Low | B11: Sedan | C11: Petrol | D11: =Assumptions!$B$45 -> 8000 | E11: =CostPerKm!$G$11 -> 7.0916667 | F11: =D11*E11 -> 56733.333 | G11: =Assumptions!$B$39 -> 6000 | H11: =F11+G11 -> 62733.333 | I11: =0 -> 0 | J11: =I11+H11*Assumptions!$B$48 -> 313666.67 | K11: =($D11*CostPerKm!$G$11+Assumptions!$B$39)-H11 -> 0 | L11: =IF(K11<=0,"never",IF(I11=0,0,I11/K11)) -> never
A12: Low | B12: Sedan | C12: Diesel | D12: =Assumptions!$B$45 -> 8000 | E12: =CostPerKm!$G$12 -> 4.3272727 | F12: =D12*E12 -> 34618.182 | G12: =Assumptions!$B$40 -> 9000 | H12: =F12+G12 -> 43618.182 | I12: =Assumptions!$C$31 -> 120000 | J12: =I12+H12*Assumptions!$B$48 -> 338090.91 | K12: =($D12*CostPerKm!$G$11+Assumptions!$B$39)-H12 -> 19115.152 | L12: =IF(K12<=0,"never",IF(I12=0,0,I12/K12)) -> 6.2777425
A13: Low | B13: Sedan | C13: CNG | D13: =Assumptions!$B$45 -> 8000 | E13: =CostPerKm!$G$13 -> 3.1957692 | F13: =D13*E13 -> 25566.154 | G13: =Assumptions!$B$41 -> 8500 | H13: =F13+G13 -> 34066.154 | I13: =Assumptions!$D$31 -> 95000 | J13: =I13+H13*Assumptions!$B$48 -> 265330.77 | K13: =($D13*CostPerKm!$G$11+Assumptions!$B$39)-H13 -> 28667.179 | L13: =IF(K13<=0,"never",IF(I13=0,0,I13/K13)) -> 3.3138942
A14: Low | B14: Sedan | C14: EV | D14: =Assumptions!$B$45 -> 8000 | E14: =CostPerKm!$G$14 -> 1.5142857 | F14: =D14*E14 -> 12114.286 | G14: =Assumptions!$B$42 -> 3500 | H14: =F14+G14 -> 15614.286 | I14: =Assumptions!$E$31 -> 500000 | J14: =I14+H14*Assumptions!$B$48 -> 578071.43 | K14: =($D14*CostPerKm!$G$11+Assumptions!$B$39)-H14 -> 47119.048 | L14: =IF(K14<=0,"never",IF(I14=0,0,I14/K14)) -> 10.61142
A15: Low | B15: Compact SUV | C15: Petrol | D15: =Assumptions!$B$45 -> 8000 | E15: =CostPerKm!$G$15 -> 8.1826923 | F15: =D15*E15 -> 65461.538 | G15: =Assumptions!$B$39 -> 6000 | H15: =F15+G15 -> 71461.538 | I15: =0 -> 0 | J15: =I15+H15*Assumptions!$B$48 -> 357307.69 | K15: =($D15*CostPerKm!$G$15+Assumptions!$B$39)-H15 -> 0 | L15: =IF(K15<=0,"never",IF(I15=0,0,I15/K15)) -> never
A16: Low | B16: Compact SUV | C16: Diesel | D16: =Assumptions!$B$45 -> 8000 | E16: =CostPerKm!$G$16 -> 5.0105263 | F16: =D16*E16 -> 40084.211 | G16: =Assumptions!$B$40 -> 9000 | H16: =F16+G16 -> 49084.211 | I16: =Assumptions!$C$32 -> 150000 | J16: =I16+H16*Assumptions!$B$48 -> 395421.05 | K16: =($D16*CostPerKm!$G$15+Assumptions!$B$39)-H16 -> 22377.328 | L16: =IF(K16<=0,"never",IF(I16=0,0,I16/K16)) -> 6.7032132
A17: Low | B17: Compact SUV | C17: CNG | D17: =Assumptions!$B$45 -> 8000 | E17: =CostPerKm!$G$17 -> 3.7768182 | F17: =D17*E17 -> 30214.545 | G17: =Assumptions!$B$41 -> 8500 | H17: =F17+G17 -> 38714.545 | I17: =Assumptions!$D$32 -> 110000 | J17: =I17+H17*Assumptions!$B$48 -> 303572.73 | K17: =($D17*CostPerKm!$G$15+Assumptions!$B$39)-H17 -> 32746.993 | L17: =IF(K17<=0,"never",IF(I17=0,0,I17/K17)) -> 3.359087
A18: Low | B18: Compact SUV | C18: EV | D18: =Assumptions!$B$45 -> 8000 | E18: =CostPerKm!$G$18 -> 1.6307692 | F18: =D18*E18 -> 13046.154 | G18: =Assumptions!$B$42 -> 3500 | H18: =F18+G18 -> 16546.154 | I18: =Assumptions!$E$32 -> 400000 | J18: =I18+H18*Assumptions!$B$48 -> 482730.77 | K18: =($D18*CostPerKm!$G$15+Assumptions!$B$39)-H18 -> 54915.385 | L18: =IF(K18<=0,"never",IF(I18=0,0,I18/K18)) -> 7.2839333
A19: Average | B19: Two-wheeler | C19: Petrol | D19: =Assumptions!$B$46 -> 15000 | E19: =CostPerKm!$G$5 -> 1.9340909 | F19: =D19*E19 -> 29011.364 | G19: =Assumptions!$B$36 -> 2000 | H19: =F19+G19 -> 31011.364 | I19: =0 -> 0 | J19: =I19+H19*Assumptions!$B$48 -> 155056.82 | K19: =($D19*CostPerKm!$G$5+Assumptions!$B$36)-H19 -> 0 | L19: =IF(K19<=0,"never",IF(I19=0,0,I19/K19)) -> never
A20: Average | B20: Two-wheeler | C20: CNG | D20: =Assumptions!$B$46 -> 15000 | E20: =CostPerKm!$G$6 -> 0.81460784 | F20: =D20*E20 -> 12219.118 | G20: =Assumptions!$B$37 -> 2600 | H20: =F20+G20 -> 14819.118 | I20: =Assumptions!$D$29 -> 15000 | J20: =I20+H20*Assumptions!$B$48 -> 89095.588 | K20: =($D20*CostPerKm!$G$5+Assumptions!$B$36)-H20 -> 16192.246 | L20: =IF(K20<=0,"never",IF(I20=0,0,I20/K20)) -> 0.92636933
A21: Average | B21: Two-wheeler | C21: EV | D21: =Assumptions!$B$46 -> 15000 | E21: =CostPerKm!$G$7 -> 0.35333333 | F21: =D21*E21 -> 5300 | G21: =Assumptions!$B$38 -> 1000 | H21: =F21+G21 -> 6300 | I21: =Assumptions!$E$29 -> 45000 | J21: =I21+H21*Assumptions!$B$48 -> 76500 | K21: =($D21*CostPerKm!$G$5+Assumptions!$B$36)-H21 -> 24711.364 | L21: =IF(K21<=0,"never",IF(I21=0,0,I21/K21)) -> 1.8210246
A22: Average | B22: Hatchback | C22: Petrol | D22: =Assumptions!$B$46 -> 15000 | E22: =CostPerKm!$G$8 -> 6.6484375 | F22: =D22*E22 -> 99726.562 | G22: =Assumptions!$B$39 -> 6000 | H22: =F22+G22 -> 105726.56 | I22: =0 -> 0 | J22: =I22+H22*Assumptions!$B$48 -> 528632.81 | K22: =($D22*CostPerKm!$G$8+Assumptions!$B$39)-H22 -> 0 | L22: =IF(K22<=0,"never",IF(I22=0,0,I22/K22)) -> never
A23: Average | B23: Hatchback | C23: CNG | D23: =Assumptions!$B$46 -> 15000 | E23: =CostPerKm!$G$9 -> 2.9675 | F23: =D23*E23 -> 44512.5 | G23: =Assumptions!$B$41 -> 8500 | H23: =F23+G23 -> 53012.5 | I23: =Assumptions!$D$30 -> 90000 | J23: =I23+H23*Assumptions!$B$48 -> 355062.5 | K23: =($D23*CostPerKm!$G$8+Assumptions!$B$39)-H23 -> 52714.062 | L23: =IF(K23<=0,"never",IF(I23=0,0,I23/K23)) -> 1.7073243
A24: Average | B24: Hatchback | C24: EV | D24: =Assumptions!$B$46 -> 15000 | E24: =CostPerKm!$G$10 -> 1.4133333 | F24: =D24*E24 -> 21200 | G24: =Assumptions!$B$42 -> 3500 | H24: =F24+G24 -> 24700 | I24: =Assumptions!$E$30 -> 450000 | J24: =I24+H24*Assumptions!$B$48 -> 573500 | K24: =($D24*CostPerKm!$G$8+Assumptions!$B$39)-H24 -> 81026.562 | L24: =IF(K24<=0,"never",IF(I24=0,0,I24/K24)) -> 5.5537343
A25: Average | B25: Sedan | C25: Petrol | D25: =Assumptions!$B$46 -> 15000 | E25: =CostPerKm!$G$11 -> 7.0916667 | F25: =D25*E25 -> 106375 | G25: =Assumptions!$B$39 -> 6000 | H25: =F25+G25 -> 112375 | I25: =0 -> 0 | J25: =I25+H25*Assumptions!$B$48 -> 561875 | K25: =($D25*CostPerKm!$G$11+Assumptions!$B$39)-H25 -> 0 | L25: =IF(K25<=0,"never",IF(I25=0,0,I25/K25)) -> never
A26: Average | B26: Sedan | C26: Diesel | D26: =Assumptions!$B$46 -> 15000 | E26: =CostPerKm!$G$12 -> 4.3272727 | F26: =D26*E26 -> 64909.091 | G26: =Assumptions!$B$40 -> 9000 | H26: =F26+G26 -> 73909.091 | I26: =Assumptions!$C$31 -> 120000 | J26: =I26+H26*Assumptions!$B$48 -> 489545.45 | K26: =($D26*CostPerKm!$G$11+Assumptions!$B$39)-H26 -> 38465.909 | L26: =IF(K26<=0,"never",IF(I26=0,0,I26/K26)) -> 3.1196455
A27: Average | B27: Sedan | C27: CNG | D27: =Assumptions!$B$46 -> 15000 | E27: =CostPerKm!$G$13 -> 3.1957692 | F27: =D27*E27 -> 47936.538 | G27: =Assumptions!$B$41 -> 8500 | H27: =F27+G27 -> 56436.538 | I27: =Assumptions!$D$31 -> 95000 | J27: =I27+H27*Assumptions!$B$48 -> 377182.69 | K27: =($D27*CostPerKm!$G$11+Assumptions!$B$39)-H27 -> 55938.462 | L27: =IF(K27<=0,"never",IF(I27=0,0,I27/K27)) -> 1.6982948
A28: Average | B28: Sedan | C28: EV | D28: =Assumptions!$B$46 -> 15000 | E28: =CostPerKm!$G$14 -> 1.5142857 | F28: =D28*E28 -> 22714.286 | G28: =Assumptions!$B$42 -> 3500 | H28: =F28+G28 -> 26214.286 | I28: =Assumptions!$E$31 -> 500000 | J28: =I28+H28*Assumptions!$B$48 -> 631071.43 | K28: =($D28*CostPerKm!$G$11+Assumptions!$B$39)-H28 -> 86160.714 | L28: =IF(K28<=0,"never",IF(I28=0,0,I28/K28)) -> 5.8031088
A29: Average | B29: Compact SUV | C29: Petrol | D29: =Assumptions!$B$46 -> 15000 | E29: =CostPerKm!$G$15 -> 8.1826923 | F29: =D29*E29 -> 122740.38 | G29: =Assumptions!$B$39 -> 6000 | H29: =F29+G29 -> 128740.38 | I29: =0 -> 0 | J29: =I29+H29*Assumptions!$B$48 -> 643701.92 | K29: =($D29*CostPerKm!$G$15+Assumptions!$B$39)-H29 -> 0 | L29: =IF(K29<=0,"never",IF(I29=0,0,I29/K29)) -> never
A30: Average | B30: Compact SUV | C30: Diesel | D30: =Assumptions!$B$46 -> 15000 | E30: =CostPerKm!$G$16 -> 5.0105263 | F30: =D30*E30 -> 75157.895 | G30: =Assumptions!$B$40 -> 9000 | H30: =F30+G30 -> 84157.895 | I30: =Assumptions!$C$32 -> 150000 | J30: =I30+H30*Assumptions!$B$48 -> 570789.47 | K30: =($D30*CostPerKm!$G$15+Assumptions!$B$39)-H30 -> 44582.49 | L30: =IF(K30<=0,"never",IF(I30=0,0,I30/K30)) -> 3.3645496
A31: Average | B31: Compact SUV | C31: CNG | D31: =Assumptions!$B$46 -> 15000 | E31: =CostPerKm!$G$17 -> 3.7768182 | F31: =D31*E31 -> 56652.273 | G31: =Assumptions!$B$41 -> 8500 | H31: =F31+G31 -> 65152.273 | I31: =Assumptions!$D$32 -> 110000 | J31: =I31+H31*Assumptions!$B$48 -> 435761.36 | K31: =($D31*CostPerKm!$G$15+Assumptions!$B$39)-H31 -> 63588.112 | L31: =IF(K31<=0,"never",IF(I31=0,0,I31/K31)) -> 1.7298831
A32: Average | B32: Compact SUV | C32: EV | D32: =Assumptions!$B$46 -> 15000 | E32: =CostPerKm!$G$18 -> 1.6307692 | F32: =D32*E32 -> 24461.538 | G32: =Assumptions!$B$42 -> 3500 | H32: =F32+G32 -> 27961.538 | I32: =Assumptions!$E$32 -> 400000 | J32: =I32+H32*Assumptions!$B$48 -> 539807.69 | K32: =($D32*CostPerKm!$G$15+Assumptions!$B$39)-H32 -> 100778.85 | L32: =IF(K32<=0,"never",IF(I32=0,0,I32/K32)) -> 3.9690869
A33: High | B33: Two-wheeler | C33: Petrol | D33: =Assumptions!$B$47 -> 25000 | E33: =CostPerKm!$G$5 -> 1.9340909 | F33: =D33*E33 -> 48352.273 | G33: =Assumptions!$B$36 -> 2000 | H33: =F33+G33 -> 50352.273 | I33: =0 -> 0 | J33: =I33+H33*Assumptions!$B$48 -> 251761.36 | K33: =($D33*CostPerKm!$G$5+Assumptions!$B$36)-H33 -> 0 | L33: =IF(K33<=0,"never",IF(I33=0,0,I33/K33)) -> never
A34: High | B34: Two-wheeler | C34: CNG | D34: =Assumptions!$B$47 -> 25000 | E34: =CostPerKm!$G$6 -> 0.81460784 | F34: =D34*E34 -> 20365.196 | G34: =Assumptions!$B$37 -> 2600 | H34: =F34+G34 -> 22965.196 | I34: =Assumptions!$D$29 -> 15000 | J34: =I34+H34*Assumptions!$B$48 -> 129825.98 | K34: =($D34*CostPerKm!$G$5+Assumptions!$B$36)-H34 -> 27387.077 | L34: =IF(K34<=0,"never",IF(I34=0,0,I34/K34)) -> 0.54770358
A35: High | B35: Two-wheeler | C35: EV | D35: =Assumptions!$B$47 -> 25000 | E35: =CostPerKm!$G$7 -> 0.35333333 | F35: =D35*E35 -> 8833.3333 | G35: =Assumptions!$B$38 -> 1000 | H35: =F35+G35 -> 9833.3333 | I35: =Assumptions!$E$29 -> 45000 | J35: =I35+H35*Assumptions!$B$48 -> 94166.667 | K35: =($D35*CostPerKm!$G$5+Assumptions!$B$36)-H35 -> 40518.939 | L35: =IF(K35<=0,"never",IF(I35=0,0,I35/K35)) -> 1.1105918
A36: High | B36: Hatchback | C36: Petrol | D36: =Assumptions!$B$47 -> 25000 | E36: =CostPerKm!$G$8 -> 6.6484375 | F36: =D36*E36 -> 166210.94 | G36: =Assumptions!$B$39 -> 6000 | H36: =F36+G36 -> 172210.94 | I36: =0 -> 0 | J36: =I36+H36*Assumptions!$B$48 -> 861054.69 | K36: =($D36*CostPerKm!$G$8+Assumptions!$B$39)-H36 -> 0 | L36: =IF(K36<=0,"never",IF(I36=0,0,I36/K36)) -> never
A37: High | B37: Hatchback | C37: CNG | D37: =Assumptions!$B$47 -> 25000 | E37: =CostPerKm!$G$9 -> 2.9675 | F37: =D37*E37 -> 74187.5 | G37: =Assumptions!$B$41 -> 8500 | H37: =F37+G37 -> 82687.5 | I37: =Assumptions!$D$30 -> 90000 | J37: =I37+H37*Assumptions!$B$48 -> 503437.5 | K37: =($D37*CostPerKm!$G$8+Assumptions!$B$39)-H37 -> 89523.438 | L37: =IF(K37<=0,"never",IF(I37=0,0,I37/K37)) -> 1.0053233
A38: High | B38: Hatchback | C38: EV | D38: =Assumptions!$B$47 -> 25000 | E38: =CostPerKm!$G$10 -> 1.4133333 | F38: =D38*E38 -> 35333.333 | G38: =Assumptions!$B$42 -> 3500 | H38: =F38+G38 -> 38833.333 | I38: =Assumptions!$E$30 -> 450000 | J38: =I38+H38*Assumptions!$B$48 -> 644166.67 | K38: =($D38*CostPerKm!$G$8+Assumptions!$B$39)-H38 -> 133377.6 | L38: =IF(K38<=0,"never",IF(I38=0,0,I38/K38)) -> 3.3738798
A39: High | B39: Sedan | C39: Petrol | D39: =Assumptions!$B$47 -> 25000 | E39: =CostPerKm!$G$11 -> 7.0916667 | F39: =D39*E39 -> 177291.67 | G39: =Assumptions!$B$39 -> 6000 | H39: =F39+G39 -> 183291.67 | I39: =0 -> 0 | J39: =I39+H39*Assumptions!$B$48 -> 916458.33 | K39: =($D39*CostPerKm!$G$11+Assumptions!$B$39)-H39 -> 0 | L39: =IF(K39<=0,"never",IF(I39=0,0,I39/K39)) -> never
A40: High | B40: Sedan | C40: Diesel | D40: =Assumptions!$B$47 -> 25000 | E40: =CostPerKm!$G$12 -> 4.3272727 | F40: =D40*E40 -> 108181.82 | G40: =Assumptions!$B$40 -> 9000 | H40: =F40+G40 -> 117181.82 | I40: =Assumptions!$C$31 -> 120000 | J40: =I40+H40*Assumptions!$B$48 -> 705909.09 | K40: =($D40*CostPerKm!$G$11+Assumptions!$B$39)-H40 -> 66109.848 | L40: =IF(K40<=0,"never",IF(I40=0,0,I40/K40)) -> 1.8151607
A41: High | B41: Sedan | C41: CNG | D41: =Assumptions!$B$47 -> 25000 | E41: =CostPerKm!$G$13 -> 3.1957692 | F41: =D41*E41 -> 79894.231 | G41: =Assumptions!$B$41 -> 8500 | H41: =F41+G41 -> 88394.231 | I41: =Assumptions!$D$31 -> 95000 | J41: =I41+H41*Assumptions!$B$48 -> 536971.15 | K41: =($D41*CostPerKm!$G$11+Assumptions!$B$39)-H41 -> 94897.436 | L41: =IF(K41<=0,"never",IF(I41=0,0,I41/K41)) -> 1.0010808
...

Sheet TaxStructure
A1: FUEL TAX STRUCTURE: WHY PETROL IS TAXED TWICE AND ETHANOL ONCE
A3: The key point
A4: Petrol and diesel are kept OUTSIDE GST. They bear TWO layers of tax: a central (federal) excise duty — a fixed Rs 13/L on petrol and Rs 10/L on diesel — PLUS a state VAT/sales tax that varies widely by state. Ethanol supplied for blending is INSIDE GST and attracts only 5% GST — a single, federally-set levy, with no separate state VAT on the ethanol molecule.
A5: So the ~20% ethanol in E20 escapes the heavy dual petroleum taxation and is taxed lightly and only federally. That lowers the tax the exchequer collects on the ethanol share, but because E20 sells at the same pump price as before, the benefit is retained in the price build-up rather than rebated to the buyer — and it shifts revenue away from state VAT toward the federally-controlled GST/excise base, one reason states have been wary.
A7: Worked example — petrol price build-up for the selected city
A8: Component | B8: Rs/L | C8: Levied by
A9: Retail pump price (E20) | B9: =Assumptions!$B$7 -> 102.12 | C9: —
A10: Central excise duty | B10: 13 | C10: CENTRE (federal)
A11: Dealer commission | B11: 3.77 | C11: —
A12: State VAT | B12: =B9-B9/(1+INDEX(Cities!$F$4:$F$9,MATCH(Assumptions!$B$6,Cities!$A$4:$A$9,0))) -> 16.592362 | C12: STATE
A13: Base + freight (implied) | B13: =B9-B10-B11-B12 -> 68.757638 | C13: refiner/OMC
A14: Total tax (central + state) | B14: =B10+B12 -> 29.592362
A15: Tax as % of pump price | B15: =B14/B9 -> 0.28978028
A16: State VAT is derived from the selected city's effective rate; base+freight is the residual. Excise Rs 13/L and dealer Rs 3.77/L are current central/indicative figures.
A18: Petrol vs ethanol — who taxes what
A19: Fuel | B19: Central levy | C19: State levy | D19: Net
A20: Petrol / Diesel | B20: Excise Rs 13 / Rs 10 per L | C20: VAT 14%-35% (varies) | D20: Dual: central + state
A21: Ethanol (for blending) | B21: 5% GST | C21: None (outside state VAT) | D21: Single: federal only

Sheet FleetSales
A1: MATCHING THE MODEL TO THE MARKET — VAHAN FLEET & FADA SALES (FY26)
A2: Do buyers behave as the value math predicts? FADA FY26 retail mix, and the national ethanol-penalty aggregate. Blue = data input. Green = computed.
A4: A. FADA FY26 retail sales by category
A5: Category | B5: Units FY26 | C5: % of total | D5: EV share in category
A6: Two-wheelers | B6: 21420386 | C6: =B6/$B$12 -> 0.72192848 | D6: 0.0654
A7: Three-wheelers | B7: 1363412 | C7: =B7/$B$12 -> 0.045950897 | D7: 0.6095
A8: Passenger vehicles | B8: 4705056 | C8: =B8/$B$12 -> 0.15857389 | D8: 0.0425
A9: Commercial vehicles | B9: 1060906 | C9: =B9/$B$12 -> 0.035755577 | D9: 0.0183
A10: Tractors | B10: 1050077 | C10: =B10/$B$12 -> 0.035390608 | D10: n/a
A11: Construction equip. | B11: 71227 | C11: =B11/$B$12 -> 0.0024005543 | D11: n/a
A12: TOTAL retail | B12: =SUM(B6:B11) -> 29671064
A14: B. Passenger-vehicle fuel mix (FADA FY26 vs FY25)
A15: Fuel | B15: FY26 share | C15: FY25 share | D15: Change (pp)
A16: Petrol | B16: 0.4748 | C16: 0.5082 | D16: =(B16-C16)*100 -> -3.34
A17: Diesel | B17: 0.1808 | C17: 0.1823 | D17: =(B17-C17)*100 -> -0.15
A18: CNG | B18: 0.2198 | C18: 0.196 | D18: =(B18-C18)*100 -> 2.38
A19: Electric | B19: 0.0425 | C19: 0.0261 | D19: =(B19-C19)*100 -> 1.64
A20: Hybrid / other | B20: 0.0821 | C20: 0.0874 | D20: =(B20-C20)*100 -> -0.53
A21: Sum (check ~100%) | B21: =SUM(B16:B20) -> 1
A23: C. Sales-weighted PV running cost (selected city)
A24: Fuel | B24: PV share (FY26) | C24: Car cost/km (Rs) | D24: Weighted (Rs/km)
A25: Petrol | B25: =B16 -> 0.4748 | C25: =CostPerKm!$G$8 -> 6.6484375 | D25: =B25*C25 -> 3.1566781
A26: Diesel | B26: =B17 -> 0.1808 | C26: =CostPerKm!$G$12 -> 4.3272727 | D26: =B26*C26 -> 0.78237091
A27: CNG | B27: =B18 -> 0.2198 | C27: =CostPerKm!$G$9 -> 2.9675 | D27: =B27*C27 -> 0.6522565
A28: Electric | B28: =B19 -> 0.0425 | C28: =CostPerKm!$G$10 -> 1.4133333 | D28: =B28*C28 -> 0.060066667
A29: Weighted-avg PV running cost | B29: =SUM(D25:D28)/SUM(B25:B28) -> 5.0674063 | C29: Rs/km (petrol+diesel+CNG+EV, normalised)
A31: D. National ethanol penalty (E20 vs E0) — illustrative aggregate
A32: Segment | B32: Petrol vehicles | C32: Extra Rs/veh/yr | D32: Total Rs crore/yr
A33: New petrol PV (FY26 cohort) | B33: =B16*B8 -> 2233960.6 | C33: =EthanolImpact!$H$6 -> 3989.0625 | D33: =B33*C33/10000000 -> 891.14084
A34: New petrol 2W (FY26 cohort) | B34: =(1-D6)*B6 -> 20019493 | C34: =EthanolImpact!$H$5 -> 1160.4545 | D34: =B34*C34/10000000 -> 2323.1711
A35: Petrol cars in fleet (parc) — EDIT | B35: 40000000 | C35: =EthanolImpact!$H$6 -> 3989.0625 | D35: =B35*C35/10000000 -> 15956.25
A36: Petrol 2W in fleet (parc) — EDIT | B36: 200000000 | C36: =EthanolImpact!$H$5 -> 1160.4545 | D36: =B36*C36/10000000 -> 23209.091
A37: Fleet ethanol penalty (parc) | D37: =D35+D36 -> 39165.341
A38: New-vehicle cohort ethanol penalty (PV+2W) | D38: =D33+D34 -> 3214.312
A40: Parc figures are illustrative editable assumptions (yellow). Rs crore = value/1,00,00,000. New-cohort figures derive from FADA FY26 units.
A42: E. Source reconciliation — SIAM wholesale vs FADA retail (FY26)
A43: Category | B43: SIAM wholesale | C43: FADA retail | D43: Retail vs wholesale
A44: Passenger vehicles | B44: 4643439 | C44: =B8 -> 4705056 | D44: =(C44-B44)/B44 -> 0.013269691
A45: Two-wheelers | B45: 21705974 | C45: =B6 -> 21420386 | D45: =(C45-B45)/B45 -> -0.013157115
A46: Three-wheelers | B46: 836231 | C46: =B7 -> 1363412 | D46: =(C46-B46)/B46 -> 0.63042509
...

Sheet OMC_PriceBoard
A1: OMC-PUBLISHED FUEL PRICES ACROSS INDIA (IOCL/BPCL/HPCL daily boards, ~July 2026)
A2: Prices as revised daily by oil marketing companies. Petrol/km & Diesel/km computed from model mileages. Blue = price input; Green = computed.
A4: City | B4: State / UT | C4: Petrol Rs/L | D4: Diesel Rs/L | E4: Petrol Rs/km (hatch) | F4: Diesel Rs/km (SUV) | G4: Petrol vs Delhi (Rs/L)
A5: Delhi | B5: Delhi | C5: 102.12 | D5: 95.2 | E5: =C5/(Assumptions!$B$22*(1-Assumptions!$B$17)) -> 6.6484375 | F5: =D5/Assumptions!$C$24 -> 5.0105263 | G5: =C5-$C$5 -> 0
A6: Chandigarh | B6: UT | C6: 101.54 | D6: 89.47 | E6: =C6/(Assumptions!$B$22*(1-Assumptions!$B$17)) -> 6.6106771 | F6: =D6/Assumptions!$C$24 -> 4.7089474 | G6: =C6-$C$5 -> -0.58
A7: Lucknow | B7: Uttar Pradesh | C7: 101.86 | D7: 95.36 | E7: =C7/(Assumptions!$B$22*(1-Assumptions!$B$17)) -> 6.6315104 | F7: =D7/Assumptions!$C$24 -> 5.0189474 | G7: =C7-$C$5 -> -0.26
A8: Noida | B8: Uttar Pradesh | C8: 101.96 | D8: 95.44 | E8: =C8/(Assumptions!$B$22*(1-Assumptions!$B$17)) -> 6.6380208 | F8: =D8/Assumptions!$C$24 -> 5.0231579 | G8: =C8-$C$5 -> -0.16
A9: Gurgaon | B9: Haryana | C9: 102.97 | D9: 95.64 | E9: =C9/(Assumptions!$B$22*(1-Assumptions!$B$17)) -> 6.703776 | F9: =D9/Assumptions!$C$24 -> 5.0336842 | G9: =C9-$C$5 -> 0.85
A10: Chennai | B10: Tamil Nadu | C10: 107.76 | D10: 99.55 | E10: =C10/(Assumptions!$B$22*(1-Assumptions!$B$17)) -> 7.015625 | F10: =D10/Assumptions!$C$24 -> 5.2394737 | G10: =C10-$C$5 -> 5.64
A11: Bhubaneswar | B11: Odisha | C11: 110.49 | D11: 100.68 | E11: =C11/(Assumptions!$B$22*(1-Assumptions!$B$17)) -> 7.1933594 | F11: =D11/Assumptions!$C$24 -> 5.2989474 | G11: =C11-$C$5 -> 8.37
A12: Bengaluru | B12: Karnataka | C12: 110.82 | D12: 99.56 | E12: =C12/(Assumptions!$B$22*(1-Assumptions!$B$17)) -> 7.2148438 | F12: =D12/Assumptions!$C$24 -> 5.24 | G12: =C12-$C$5 -> 8.7
A13: Mumbai | B13: Maharashtra | C13: 111.21 | D13: 97.83 | E13: =C13/(Assumptions!$B$22*(1-Assumptions!$B$17)) -> 7.2402344 | F13: =D13/Assumptions!$C$24 -> 5.1489474 | G13: =C13-$C$5 -> 9.09
A14: Jaipur | B14: Rajasthan | C14: 112.66 | D14: 98.25 | E14: =C14/(Assumptions!$B$22*(1-Assumptions!$B$17)) -> 7.3346354 | F14: =D14/Assumptions!$C$24 -> 5.1710526 | G14: =C14-$C$5 -> 10.54
A15: Kolkata | B15: West Bengal | C15: 113.51 | D15: 99.82 | E15: =C15/(Assumptions!$B$22*(1-Assumptions!$B$17)) -> 7.389974 | F15: =D15/Assumptions!$C$24 -> 5.2536842 | G15: =C15-$C$5 -> 11.39
A16: Patna | B16: Bihar | C16: 113.53 | D16: 99.36 | E16: =C16/(Assumptions!$B$22*(1-Assumptions!$B$17)) -> 7.391276 | F16: =D16/Assumptions!$C$24 -> 5.2294737 | G16: =C16-$C$5 -> 11.41
... A18: Hyderabad | B18: Telangana | C18: 115.69 | D18: 103.82 | E18: =C18/(Assumptions!$B$22*(1-Assumptions!$B$17)) -> 7.531901 | F18: =D18/Assumptions!$C$24 -> 5.4642105 | G18: =C18-$C$5 -> 13.57
A20: Lowest petrol (Rs/L) | C20: =MIN(C5:C18) -> 101.54
A21: Highest petrol (Rs/L) | C21: =MAX(C5:C18) -> 115.69
A22: Petrol spread (Rs/L) | C22: =MAX(C5:C18)-MIN(C5:C18) -> 14.15
A23: Petrol spread (%) | C23: =(MAX(C5:C18)-MIN(C5:C18))/MIN(C5:C18) -> 0.13935395
A24: Diesel spread (Rs/L) | C24: =MAX(D5:D18)-MIN(D5:D18) -> 14.93
A25: Same car, same E20 fuel: running cost swings across states purely on tax. Central excise is uniform; the spread is state VAT.

Sheet ExchequerRevenue
A1: EXCHEQUER EARNINGS FROM VEHICLES, VKT & FUEL TAX (PPAC / PIB / MoPNG basis, FY26)
A2: How growth in vehicles and kilometres feeds tax revenue. Blue = input (edit). Green = computed. All ₹ in lakh crore unless noted.
A4: A. Fuel consumption (PPAC FY26) → litres
A5: Petrol (MS) consumption | B5: 42.663 | C5: MMT | D5: PPAC FY26 estimate
A6: Diesel (HSD) consumption | B6: 93.946 | C6: MMT | D6: PPAC FY26 estimate
A7: Petrol density | B7: 0.74 | C7: kg/L | D7: Typical
A8: Diesel density | B8: 0.83 | C8: kg/L | D8: Typical
A9: Petrol volume | B9: =ExchequerRevenue!$B$5*100/ExchequerRevenue!$B$7 -> 5765.2703 | C9: crore L | D9: 1 MMT = 100/density crore L
A10: Diesel volume | B10: =ExchequerRevenue!$B$6*100/ExchequerRevenue!$B$8 -> 11318.795 | C10: crore L
A11: B. Recurring fuel-tax revenue (excise + VAT)
A12: Central excise - petrol | B12: 13 | C12: Rs/L | D12: Uniform, federal
A13: Central excise - diesel | B13: 10 | C13: Rs/L | D13: Uniform, federal
A14: State VAT - petrol (national avg) | B14: 18 | C14: Rs/L | D14: Blended est.; states vary 14-35%
A15: State VAT - diesel (national avg) | B15: 12 | C15: Rs/L | D15: Blended est.
A16: Central excise revenue | B16: =(ExchequerRevenue!$B$9*ExchequerRevenue!$B$12+ExchequerRevenue!$B$10*ExchequerRevenue!$B$13)/100000 -> 1.8813647 | C16: lakh cr | D16: Petrol+diesel excise
A17: State VAT revenue | B17: =(ExchequerRevenue!$B$9*ExchequerRevenue!$B$14+ExchequerRevenue!$B$10*ExchequerRevenue!$B$15)/100000 -> 2.3960041 | C17: lakh cr | D17: Petrol+diesel VAT
A18: TOTAL recurring fuel tax | B18: =ExchequerRevenue!$B$16+ExchequerRevenue!$B$17 -> 4.2773687 | C18: lakh cr | D18: Centre + states
A19: C. One-time GST + cess on new vehicles (FADA FY26, GST 2.0)
A20: Two-wheeler avg price | B20: 90000 | C20: Rs | D20: Ex-showroom est.
A21: Two-wheeler GST rate | B21: 0.18 | C21: % | D21: <=350cc slab
A22: PV avg price | B22: 1000000 | C22: Rs | D22: Ex-showroom est.
A23: PV blended GST+cess | B23: 0.279 | C23: % | D23: ~55% small@18% + 45% large/SUV@40%
A24: 2W new-vehicle GST | B24: =FleetSales!$B$6*ExchequerRevenue!$B$20*ExchequerRevenue!$B$21/1000000000000 -> 0.34701025 | C24: lakh cr | D24: FADA 2W units x price x rate
A25: PV new-vehicle GST | B25: =FleetSales!$B$8*ExchequerRevenue!$B$22*ExchequerRevenue!$B$23/1000000000000 -> 1.3127106 | C25: lakh cr | D25: FADA PV units x price x rate
A26: TOTAL new-vehicle GST (2W+PV) | B26: =ExchequerRevenue!$B$24+ExchequerRevenue!$B$25 -> 1.6597209 | C26: lakh cr | D26: One-time, on FY26 sales
A27: D. Additional annual earnings from GROWTH
A28: Petrol consumption growth | B28: 0.07 | C28: %/yr | D28: Rising personal-vehicle use (PPAC)
A29: Diesel consumption growth | B29: 0.04 | C29: %/yr | D29: Freight/industrial (PPAC)
A30: New-vehicle sales growth | B30: 0.133 | C30: %/yr | D30: FADA FY26 +13.3%
A31: Add'l petrol tax from growth | B31: =(ExchequerRevenue!$B$9*(ExchequerRevenue!$B$12+ExchequerRevenue!$B$14))/100000*ExchequerRevenue!$B$28 -> 0.12510636 | C31: lakh cr | D31: Volume growth x petrol tax/L
A32: Add'l diesel tax from growth | B32: =(ExchequerRevenue!$B$10*(ExchequerRevenue!$B$13+ExchequerRevenue!$B$15))/100000*ExchequerRevenue!$B$29 -> 0.099605398 | C32: lakh cr
A33: Add'l vehicle GST from growth | B33: =ExchequerRevenue!$B$26*ExchequerRevenue!$B$30 -> 0.22074288 | C33: lakh cr | D33: Sales growth x vehicle-GST base
A34: TOTAL additional earnings/yr | B34: =ExchequerRevenue!$B$31+ExchequerRevenue!$B$32+ExchequerRevenue!$B$33 -> 0.44545464 | C34: lakh cr | D34: From growth alone, rates constant
A35: E. Emerging erosion — fuel-mix shift (headwind)
A36: Ethanol share of petrol (E20) | B36: 0.2 | C36: % | D36: Blended into every litre
A37: Tax gap: petrol vs ethanol | B37: 28 | C37: Rs/L | D37: ~Rs31 petrol tax vs ~Rs3 on ethanol (5% GST)
A38: Revenue foregone on ethanol | B38: =ExchequerRevenue!$B$9*ExchequerRevenue!$B$36*ExchequerRevenue!$B$37/100000 -> 0.32285514 | C38: lakh cr | D38: Ethanol litres taxed light, not full
A39: Plus: every EV/CNG sale pays 5% GST (vs 18-40% ICE) and burns no taxed petrol/diesel — a growing structural drag on both streams above.
A41: Bottom line: vehicle + VKT growth adds ~Rs 0 (see D) to the exchequer each year at constant rates; the EV/CNG/ethanol shift is the offsetting headwind (E). Fuel tax = outside GST (excise+VAT); vehicles & ethanol = inside GST.

Sheet Checks
A1: DATA CONSISTENCY CHECKS
A2: All should read PASS.
A4: Check | B4: Result
A5: Selected city found in Cities table | B5: =IF(ISNUMBER(MATCH(Assumptions!$B$6,Cities!$A$4:$A$9,0)),"PASS","FAIL") -> PASS
A6: Effective E20 mileage < E0 baseline (Hatchback) | B6: =IF(CostPerKm!$D$8<Assumptions!$B$22,"PASS","FAIL") -> PASS
A7: CNG cost/km < Petrol cost/km (Hatchback) | B7: =IF(CostPerKm!$G$9<CostPerKm!$G$8,"PASS","FAIL") -> PASS
A8: Diesel cost/km < Petrol cost/km (Compact SUV) | B8: =IF(CostPerKm!$G$16<CostPerKm!$G$15,"PASS","FAIL") -> PASS
A9: EV cost/km < CNG cost/km (Hatchback) | B9: =IF(CostPerKm!$G$10<CostPerKm!$G$9,"PASS","FAIL") -> PASS
A10: Blended electricity between home and public | B10: =IF(AND(Assumptions!$B$15>=MIN(Assumptions!$B$10,Assumptions!$B$13),Assumptions!$B$15<=MAX(Assumptions!$B$10,Assumptions!$B$13)),"PASS","FAIL") -> PASS
A11: Home charging share 0-100% | B11: =IF(AND(Assumptions!$B$14>=0,Assumptions!$B$14<=1),"PASS","FAIL") -> PASS
A12: E20 drop >= E10 drop | B12: =IF(Assumptions!$B$17>=Assumptions!$B$16,"PASS","FAIL") -> PASS
A13: All cost/km positive | B13: =IF(MIN(CostPerKm!G5:G100)>0,"PASS","FAIL") -> PASS
A14: High > Average > Low usage | B14: =IF(AND(Assumptions!$B$47>Assumptions!$B$46,Assumptions!$B$46>Assumptions!$B$45),"PASS","FAIL") -> PASS
A15: Annual total = fuel + maint (TCO row 5) | B15: =IF(ABS(TCO_Scenarios!H5-(TCO_Scenarios!F5+TCO_Scenarios!G5))<0.01,"PASS","FAIL") -> PASS
A16: No negative payback | B16: =IF(SUMPRODUCT(--ISNUMBER(TCO_Scenarios!L5:L46),--(TCO_Scenarios!L5:L46<0))=0,"PASS","FAIL") -> PASS
A17: City petrol/km within 20% of full model (Hatch) | B17: =IF(ABS(INDEX(Cities!$H$4:$H$9,MATCH(Assumptions!$B$6,Cities!$A$4:$A$9,0))-CostPerKm!$G$8)<0.2*CostPerKm!$G$8,"PASS","FAIL") -> PASS
A18: FADA PV fuel shares sum to ~100% | B18: =IF(ABS(FleetSales!$B$21-1)<0.005,"PASS","FAIL") -> PASS
A19: Sales-weighted PV cost between EV and petrol | B19: =IF(AND(FleetSales!$B$29>CostPerKm!$G$10,FleetSales!$B$29<CostPerKm!$G$8),"PASS","FAIL") -> PASS
A20: SIAM & FADA PV totals agree within 5% | B20: =IF(ABS(FleetSales!$D$44)<0.05,"PASS","FAIL") -> PASS
A21: OMC board: Delhi petrol matches Cities tab | B21: =IF(ABS(OMC_PriceBoard!$C$5-INDEX(Cities!$B$4:$B$9,MATCH("Delhi",Cities!$A$4:$A$9,0)))<0.01,"PASS","FAIL") -> PASS
A22: OMC board: petrol max > min (positive spread) | B22: =IF(OMC_PriceBoard!$C$21>OMC_PriceBoard!$C$20,"PASS","FAIL") -> PASS
A23: Exchequer: central + state = total fuel tax | B23: =IF(ABS((ExchequerRevenue!$B$16+ExchequerRevenue!$B$17)-ExchequerRevenue!$B$18)<0.001,"PASS","FAIL") -> PASS
A24: Exchequer: recurring fuel tax in 3-6 lakh cr range | B24: =IF(AND(ExchequerRevenue!$B$18>3,ExchequerRevenue!$B$18<6),"PASS","FAIL") -> PASS
A25: Exchequer: additional earnings positive | B25: =IF(ExchequerRevenue!$B$34>0,"PASS","FAIL") -> PASS
A27: Overall | B27: =IF(COUNTIF(B5:B25,"FAIL")=0,"ALL PASS","REVIEW FAILS") -> ALL PASS
